<?xml version="1.0" encoding="utf-8"?>
<!-- =================================================================================== -->
<!-- |    This document was autogenerated by xacro from niryo_ned_gripper1_n_camera.urdf.xacro | -->
<!-- |    EDITING THIS FILE BY HAND IS NOT RECOMMENDED                                 | -->
<!-- =================================================================================== -->
<robot name="niryo_ned">
  <!-- Enable Gazebo control-->
  <gazebo>
    <plugin filename="libgazebo_ros_control.so" name="gazebo_ros_control">
      <robotSimType>gazebo_ros_control/DefaultRobotHWSim</robotSimType>
    </plugin>
  </gazebo>
  <!-- Properties -->
  <!-- Links -->
  <link name="world"/>
  <joint name="joint_world" type="fixed">
    <parent link="world"/>
    <child link="base_link"/>
    <origin rpy="0 0 0" xyz="0 0 0"/>
  </joint>
  <link name="base_link">
    <inertial>
      <origin rpy="0 0 0" xyz="-0.00240796011216664 -0.00591764669105095 0.0515774030380053"/>
      <mass value="0.999243361008122"/>
      <inertia ixx="0.002" ixy="0.0" ixz="0.0" iyy="0.002" iyz="0.0" izz="0.004"/>
    </inertial>
    <visual>
      <origin rpy="0 0 0" xyz="0 0 0"/>
      <geometry>
        <mesh filename="package://niryo_robot_description/meshes/ned/collada/base_link.dae"/>
      </geometry>
    </visual>
    <collision>
      <origin rpy="0 0 0" xyz="0 0 0"/>
      <geometry>
        <mesh filename="package://niryo_robot_description/meshes/ned/stl/base_link.stl"/>
      </geometry>
    </collision>
  </link>
  <!--Joints -->
  <joint name="joint_1" type="revolute">
    <origin rpy="0 0 0" xyz="0 0 0.1065"/>
    <parent link="base_link"/>
    <child link="shoulder_link"/>
    <axis xyz="0 0 1"/>
    <limit effort="10.0" lower="-2.96705972839" upper="2.96705972839" velocity="2.2"/>
  </joint>
  <link name="shoulder_link">
    <inertial>
      <origin rpy="0 0 0" xyz="-0.0307310771918448 0.00581074732334248 0.0302277607274943"/>
      <mass value="0.474558968160783"/>
      <inertia ixx="0.0015" ixy="0.0" ixz="0.0" iyy="0.0015" iyz="0.0" izz="0.0015"/>
    </inertial>
    <visual>
      <origin rpy="0 0 0" xyz="0 0 0"/>
      <geometry>
        <mesh filename="package://niryo_robot_description/meshes/ned/collada/shoulder_link.dae"/>
      </geometry>
    </visual>
    <collision>
      <origin rpy="0 0 0" xyz="0 0 0"/>
      <geometry>
        <mesh filename="package://niryo_robot_description/meshes/ned/stl/shoulder_link.stl"/>
      </geometry>
    </collision>
  </link>
  <joint name="joint_2" type="revolute">
    <origin rpy="1.5707963268 -1.5707963268 0" xyz="0 0 0.065"/>
    <parent link="shoulder_link"/>
    <child link="arm_link"/>
    <axis xyz="0 0 1"/>
    <limit effort="10.0" lower="-2.09003177926" upper="0.610167106497" velocity="2.2"/>
  </joint>
  <link name="arm_link">
    <inertial>
      <origin rpy="0 0 0" xyz="0.116485160625991 -0.00141190194997476 -0.00338105503061108"/>
      <mass value="0.513332159226246"/>
      <inertia ixx="0.0015" ixy="0.0" ixz="0.0" iyy="0.0015" iyz="0.0" izz="0.0015"/>
    </inertial>
    <visual>
      <origin rpy="0 0 0" xyz="0 0 0"/>
      <geometry>
        <mesh filename="package://niryo_robot_description/meshes/ned/collada/arm_link.dae"/>
      </geometry>
    </visual>
    <collision>
      <origin rpy="0 0 0" xyz="0 0 0"/>
      <geometry>
        <mesh filename="package://niryo_robot_description/meshes/ned/stl/arm_link.stl"/>
      </geometry>
    </collision>
  </link>
  <joint name="joint_3" type="revolute">
    <origin rpy="0 0 -1.5707963268" xyz="0.221 -0.012 0"/>
    <parent link="arm_link"/>
    <child link="elbow_link"/>
    <axis xyz="0 0 1"/>
    <limit effort="7.0" lower="-1.34006379968" upper="1.57009819509" velocity="2.0"/>
  </joint>
  <link name="elbow_link">
    <inertial>
      <origin rpy="0 0 0" xyz="0.00840548736069937 0.0235132719991579 0.00139784606943909"/>
      <mass value="0.201038841892435"/>
      <inertia ixx="0.0015" ixy="0.0" ixz="0.0" iyy="0.0015" iyz="0.0" izz="0.0015"/>
    </inertial>
    <visual>
      <origin rpy="0 0 0" xyz="0 0 0"/>
      <geometry>
        <mesh filename="package://niryo_robot_description/meshes/ned/collada/elbow_link.dae"/>
      </geometry>
    </visual>
    <collision>
      <origin rpy="0 0 0" xyz="0 0 0"/>
      <geometry>
        <mesh filename="package://niryo_robot_description/meshes/ned/stl/elbow_link.stl"/>
      </geometry>
    </collision>
  </link>
  <joint name="joint_4" type="revolute">
    <origin rpy="0 1.5707963268 0" xyz="0.047 0.0325 0"/>
    <parent link="elbow_link"/>
    <child link="forearm_link"/>
    <axis xyz="0 0 1"/>
    <limit effort="7.0" lower="-2.09003177926" upper="2.09003177926" velocity="2.0"/>
  </joint>
  <link name="forearm_link">
    <inertial>
      <origin rpy="0 0 0" xyz="-0.00811345462189901 -0.000135618649565461 0.107402242790047"/>
      <mass value="0.203543862275952"/>
      <inertia ixx="0.0015" ixy="0.0" ixz="0.0" iyy="0.0015" iyz="0.0" izz="0.0015"/>
    </inertial>
    <visual>
      <origin rpy="0 0 0" xyz="0 0 0"/>
      <geometry>
        <mesh filename="package://niryo_robot_description/meshes/ned/collada/forearm_link.dae"/>
      </geometry>
    </visual>
    <collision>
      <origin rpy="0 0 0" xyz="0 0 0"/>
      <geometry>
        <mesh filename="package://niryo_robot_description/meshes/ned/stl/forearm_link.stl"/>
      </geometry>
    </collision>
  </link>
  <!-- add collision for the motor of joint 5 -->
  <link name="joint5_motor">
    <inertial>
      <origin rpy="0 0 0" xyz="-0.00811345462189901 -0.000135618649565461 0.107402242790047"/>
      <mass value="0.203543862275952"/>
      <inertia ixx="0.0015" ixy="0.0" ixz="0.0" iyy="0.0015" iyz="0.0" izz="0.0015"/>
    </inertial>
    <collision>
      <origin rpy="0 0 0" xyz="-0.045 0.0 0.1765"/>
      <geometry>
        <!-- <box size="0.03 0.03 0.046"/>  -->
        <box size="0.0435 0.0285 0.0465"/>
      </geometry>
    </collision>
  </link>
  <joint name="joint_test" type="fixed">
    <origin rpy="0 0 0" xyz="0 0 0"/>
    <parent link="forearm_link"/>
    <child link="joint5_motor"/>
  </joint>
  <joint name="joint_5" type="revolute">
    <origin rpy="3.14159265359 -1.5707963268 3.14159265359" xyz="0 0 0.188"/>
    <parent link="forearm_link"/>
    <child link="wrist_link"/>
    <axis xyz="0 0 1"/>
    <limit effort="6.0" lower="-1.92003671012" upper="1.05016461093" velocity="2.0"/>
  </joint>
  <link name="wrist_link">
    <inertial>
      <origin rpy="0 0 0" xyz="-0.0193227036920796 -0.00157014407079775 0.000275751023741896"/>
      <mass value="0.0403595377880338"/>
      <inertia ixx="0.0015" ixy="0.0" ixz="0.0" iyy="0.0015" iyz="0.0" izz="0.0015"/>
    </inertial>
    <visual>
      <origin rpy="0 0 0" xyz="0 0 0"/>
      <geometry>
        <mesh filename="package://niryo_robot_description/meshes/ned/collada/wrist_link.dae"/>
      </geometry>
    </visual>
    <collision>
      <origin rpy="0 0 0" xyz="0 0 0"/>
      <geometry>
        <mesh filename="package://niryo_robot_description/meshes/ned/stl/wrist_link.stl"/>
      </geometry>
    </collision>
  </link>
  <joint name="joint_6" type="revolute">
    <origin rpy="0 1.5707963268 0" xyz="0.0197 0.00925 0"/>
    <parent link="wrist_link"/>
    <child link="hand_link"/>
    <axis xyz="0 0 1"/>
    <limit effort="5.0" lower="-2.53002928369" upper="2.53002928369" velocity="2.0"/>
  </joint>
  <link name="hand_link">
    <inertial>
      <origin rpy="0 0 0" xyz="-5.84141230982198E-10 -1.35851692194544E-05 0.00881600136229516"/>
      <mass value="0.0148769800713074"/>
      <inertia ixx="0.0015" ixy="0.0" ixz="0.0" iyy="0.0015" iyz="0.0" izz="0.0015"/>
    </inertial>
    <visual>
      <origin rpy="0 0 0" xyz="0 0 0"/>
      <geometry>
        <mesh filename="package://niryo_robot_description/meshes/ned/collada/hand_link.dae"/>
      </geometry>
    </visual>
    <collision>
      <origin rpy="0 0 0" xyz="0 0 0"/>
      <geometry>
        <mesh filename="package://niryo_robot_description/meshes/ned/stl/hand_link.stl"/>
      </geometry>
    </collision>
  </link>
  <joint name="hand_tool_joint" type="fixed">
    <parent link="hand_link"/>
    <child link="tool_link"/>
    <origin rpy="-1.5707963268 -1.5707963268 0" xyz="0 0 0.0215"/>
  </joint>
  <link name="tool_link">
    </link>
  <transmission name="transmission_1">
    <type>transmission_interface/SimpleTransmission</type>
    <joint name="joint_1">
      <hardwareInterface>hardware_interface/PositionJointInterface</hardwareInterface>
    </joint>
    <actuator name="motor_1">
      <mechanicalReduction>1</mechanicalReduction>
    </actuator>
  </transmission>
  <transmission name="transmission_2">
    <type>transmission_interface/SimpleTransmission</type>
    <joint name="joint_2">
      <hardwareInterface>hardware_interface/PositionJointInterface</hardwareInterface>
    </joint>
    <actuator name="motor_2">
      <mechanicalReduction>1</mechanicalReduction>
    </actuator>
  </transmission>
  <transmission name="transmission_3">
    <type>transmission_interface/SimpleTransmission</type>
    <joint name="joint_3">
      <hardwareInterface>hardware_interface/PositionJointInterface</hardwareInterface>
    </joint>
    <actuator name="motor_3">
      <mechanicalReduction>1</mechanicalReduction>
    </actuator>
  </transmission>
  <transmission name="transmission_4">
    <type>transmission_interface/SimpleTransmission</type>
    <joint name="joint_4">
      <hardwareInterface>hardware_interface/PositionJointInterface</hardwareInterface>
    </joint>
    <actuator name="motor_4">
      <mechanicalReduction>1</mechanicalReduction>
    </actuator>
  </transmission>
  <transmission name="transmission_5">
    <type>transmission_interface/SimpleTransmission</type>
    <joint name="joint_5">
      <hardwareInterface>hardware_interface/PositionJointInterface</hardwareInterface>
    </joint>
    <actuator name="motor_5">
      <mechanicalReduction>1</mechanicalReduction>
    </actuator>
  </transmission>
  <transmission name="transmission_6">
    <type>transmission_interface/SimpleTransmission</type>
    <joint name="joint_6">
      <hardwareInterface>hardware_interface/PositionJointInterface</hardwareInterface>
    </joint>
    <actuator name="motor_6">
      <mechanicalReduction>1</mechanicalReduction>
    </actuator>
  </transmission>
  <!-- Joint for camera -->
  <joint name="camera_joint" type="fixed">
    <axis xyz="0 0 1"/>
    <origin rpy="-1.5707963268 0 0" xyz="0 0.0385 0"/>
    <parent link="wrist_link"/>
    <child link="camera_link"/>
  </joint>
  <!-- Camera link -->
  <link name="camera_link">
    <visual>
      <origin rpy="0 0 0" xyz="0 0 0"/>
      <geometry>
        <box size="0.01 0.037 0.037"/>
      </geometry>
      <material name="DarkGrey"/>
    </visual>
  </link>
  <!-- Add gazebo settings to make the link an camera ! -->
  <gazebo reference="camera_link">
    <material>Gazebo/DarkGrey</material>
    <sensor name="camera_gazebo" type="camera">
      <update_rate>15.0</update_rate>
      <camera name="head">
        <!--69,33 degrees-->
        <horizontal_fov>1.21</horizontal_fov>
        <!--  <aspect_ratio>1.333</aspect_ratio>-->
        <image>
          <width>640</width>
          <height>480</height>
          <format>R8G8B8</format>
        </image>
        <clip>
          <near>0.03</near>
          <far>2</far>
        </clip>
        <distortion>
          <k1>-0.4146402</k1>
          <k2>0.2407384</k2>
          <p1>-0.0</p1>
          <p2>-0.0</p2>
          <k3>-0.1040042</k3>
          <center>0.5 0.5</center>
        </distortion>
      </camera>
      <plugin filename="libgazebo_ros_camera.so" name="camera_controller">
        <alwaysOn>true</alwaysOn>
        <updateRate>0.0</updateRate>
        <cameraName>gazebo_camera</cameraName>
        <imageTopicName>image_raw</imageTopicName>
        <cameraInfoTopicName>camera_info</cameraInfoTopicName>
        <frameName>camera_link</frameName>
      </plugin>
    </sensor>
  </gazebo>
  <!-- gazebo joint state publisher for all joints. Necessary to control mors -->
  <gazebo>
    <plugin filename="libgazebo_ros_joint_state_publisher.so" name="passive_joint_state_publisher">
      <jointName>joint_1, joint_2, joint_3, joint_4, joint_5, joint_6,
                joint_base_to_mors_1, joint_base_to_mors_2
            </jointName>
      <updateRate>50.0</updateRate>
      <alwaysOn>true</alwaysOn>
    </plugin>
  </gazebo>
  <!-- Joint from tool_link to base_gripper -->
  <joint name="joint_to_gripper" type="fixed">
    <parent link="tool_link"/>
    <child link="base_gripper_1"/>
    <origin rpy="0 1.5707963268 1.5707963268" xyz="0 0 0.005"/>
  </joint>
  <!-- Base Gripper -->
  <link name="base_gripper_1">
    <inertial>
      <origin rpy="0 0 0" xyz="0.0028582 0.0022204 0.023772"/>
      <mass value="0.001"/>
      <inertia ixx="1E-06" ixy="0.0" ixz="0.0" iyy="1E-06" iyz="0.0" izz="1E-06"/>
    </inertial>
    <visual>
      <origin rpy="0 0 0" xyz="0 0 0"/>
      <geometry>
        <mesh filename="package://niryo_robot_description/meshes/gripper_1/base_gripper_1.STL"/>
      </geometry>
    </visual>
    <collision>
      <origin rpy="0 0 0" xyz="0 0 0"/>
      <geometry>
        <mesh filename="package://niryo_robot_description/meshes/gripper_1/base_gripper_1.STL"/>
      </geometry>
    </collision>
  </link>
  <!-- Mors 1 -->
  <link name="mors_1">
    <inertial>
      <origin rpy="0 0 0" xyz="-0.0049739 0.0067393 -0.023929"/>
      <mass value="0.0067248"/>
      <inertia ixx="1.1778E-06" ixy="-2.1129E-08" ixz="1.0185E-07" iyy="1.3054E-06" iyz="1.7669E-07" izz="4.3534E-07"/>
    </inertial>
    <visual>
      <origin rpy="0 0 0" xyz="0 0 0"/>
      <geometry>
        <mesh filename="package://niryo_robot_description/meshes//gripper_1/mors_1.STL"/>
      </geometry>
      <material name="">
        <color rgba="0.49804 0.49804 0.49804 1"/>
      </material>
    </visual>
    <collision>
      <origin rpy="0 0 0" xyz="0 0 0"/>
      <geometry>
        <mesh filename="package://niryo_robot_description/meshes//gripper_1/mors_1.STL"/>
      </geometry>
    </collision>
  </link>
  <joint name="joint_base_to_mors_1" type="prismatic">
    <origin rpy="1.5708 0 0" xyz="0.01455 -0.0796 0.0096137"/>
    <parent link="base_gripper_1"/>
    <child link="mors_1"/>
    <axis xyz="0 1 0"/>
    <limit effort="1" lower="-0.01" upper="0.01" velocity="5"/>
  </joint>
  <!-- Mors 2 -->
  <link name="mors_2">
    <inertial>
      <origin rpy="0 0 0" xyz="-0.0049739 -0.0067393 -0.023929"/>
      <mass value="0.0067248"/>
      <inertia ixx="1.1778E-06" ixy="2.1129E-08" ixz="1.0185E-07" iyy="1.3054E-06" iyz="-1.7669E-07" izz="4.3534E-07"/>
    </inertial>
    <visual>
      <origin rpy="0 0 0" xyz="0 0 0"/>
      <geometry>
        <mesh filename="package://niryo_robot_description/meshes/gripper_1/mors_2.STL"/>
      </geometry>
    </visual>
    <collision>
      <origin rpy="0 0 0" xyz="0 0 0"/>
      <geometry>
        <mesh filename="package://niryo_robot_description/meshes/gripper_1/mors_2.STL"/>
      </geometry>
    </collision>
  </link>
  <joint name="joint_base_to_mors_2" type="prismatic">
    <origin rpy="1.5708 0 0" xyz="0.01455 -0.0796 -0.011066"/>
    <parent link="base_gripper_1"/>
    <child link="mors_2"/>
    <axis xyz="0 -1 0"/>
    <limit effort="1" lower="-0.01" upper="0.01" velocity="5"/>
  </joint>
  <transmission name="transmission_7">
    <type>transmission_interface/SimpleTransmission</type>
    <joint name="joint_base_to_mors_1">
      <hardwareInterface>hardware_interface/EffortJointInterface</hardwareInterface>
    </joint>
    <actuator name="motor_7">
      <mechanicalReduction>1</mechanicalReduction>
    </actuator>
  </transmission>
  <transmission name="transmission_8">
    <type>transmission_interface/SimpleTransmission</type>
    <joint name="joint_base_to_mors_2">
      <hardwareInterface>hardware_interface/EffortJointInterface</hardwareInterface>
    </joint>
    <actuator name="motor_8">
      <mechanicalReduction>1</mechanicalReduction>
    </actuator>
  </transmission>
  <!-- material -->
  <gazebo reference="base_gripper_1">
    <material>Gazebo/DarkGrey</material>
  </gazebo>
  <gazebo reference="mors_1">
    <material>Gazebo/DarkGrey</material>
  </gazebo>
  <gazebo reference="mors_2">
    <material>Gazebo/DarkGrey</material>
  </gazebo>
</robot>
